Workbook

Sheet Register
A1: Radiology Room E.D. Vol B - Submittal Register
A2: Yellow cells are inputs. Required Approval = Install Date - Lead Time. Required Submit = Install Date - (Lead + Review + Prep). Orange rows need a human decision (see Review Queue).
A4: Sub # | B4: Rev | C4: Description | D4: Spec Section | E4: Section Title | F4: Type | G4: Spec Ref | H4: Install Date | I4: Lead Time (wk) | J4: Review (wk) | K4: Prep (wk) | L4: Required Approval | M4: Required Submit | N4: Actual Submit | O4: Approval Date | P4: Status | Q4: Days to Due | R4: Origin | S4: Notes | T4: Spec Text
A5: 012100.01 | B5: 0 | C5: Submit proposals for purchase of products or systems included in allowances in the form specified for Change Orders. | D5: 01 21 00 | E5: Allowances | F5: REPORT | G5: 1.4.A p.18 | J5: ='Project Rules'!$B$5 | K5: ='Project Rules'!$B$6 | L5: =IF(OR(H5="",I5=""),"",H5-7*I5) | M5: =IF(OR(H5="",I5=""),"",H5-7*(I5+J5+K5)) | P5: Not Started | Q5: =IF(OR(M5="",P5="Approved",P5="Approved as Noted"),"",M5-TODAY()) | R5: Spec article | T5: Submit proposals for purchase of products or systems included in allowances in the form specified for Change Orders.
A6: 012100.02 | B6: 0 | C6: Invoices or delivery slips showing actual quantities of allowance materials delivered | D6: 01 21 00 | E6: Allowances | F6: REPORT | G6: 1.5.A p.18 | J6: ='Project Rules'!$B$5 | K6: ='Project Rules'!$B$6 | L6: =IF(OR(H6="",I6=""),"",H6-7*I6) | M6: =IF(OR(H6="",I6=""),"",H6-7*(I6+J6+K6)) | P6: Not Started | Q6: =IF(OR(M6="",P6="Approved",P6="Approved as Noted"),"",M6-TODAY()) | R6: Spec article | T6: Submit invoices or delivery slips to show actual quantities of materials delivered to the site for use in fulfillment of each allowance.
A7: 012100.03 | B7: 0 | C7: Time sheets and documentation of labor time and cost for allowance installation | D7: 01 21 00 | E7: Allowances | F7: REPORT | G7: 1.5.B p.18 | J7: ='Project Rules'!$B$5 | K7: ='Project Rules'!$B$6 | L7: =IF(OR(H7="",I7=""),"",H7-7*I7) | M7: =IF(OR(H7="",I7=""),"",H7-7*(I7+J7+K7)) | P7: Not Started | Q7: =IF(OR(M7="",P7="Approved",P7="Approved as Noted"),"",M7-TODAY()) | R7: Spec article | T7: Submit time sheets and other documentation to show labor time and cost for installation of allowance items that include installation as part of the allowance.
A8: 012900.01 | B8: 0 | C8: Schedule of values (AIA G703 format, one line per spec section) | D8: 01 29 00 | E8: Payment Procedures | F8: SCHED | G8: 1.3.A.2 p.28 | J8: ='Project Rules'!$B$5 | K8: ='Project Rules'!$B$6 | L8: =IF(OR(H8="",I8=""),"",H8-7*I8) | M8: =IF(OR(H8="",I8=""),"",H8-7*(I8+J8+K8)) | P8: Not Started | Q8: =IF(OR(M8="",P8="Approved",P8="Approved as Noted"),"",M8-TODAY()) | R8: Added by Claude | S8: Due 7 days before the first Application for Payment | T8: Submit the schedule of values to Architect at earliest possible date, but no later than seven days before the date scheduled for submittal of initial Applications for Payment.
A9: 012900.02 | B9: 0 | C9: Draft Application for Payment (7 days before due date) | D9: 01 29 00 | E9: Payment Procedures | F9: REPORT | G9: 1.4.A.1 p.28 | J9: ='Project Rules'!$B$5 | K9: ='Project Rules'!$B$6 | L9: =IF(OR(H9="",I9=""),"",H9-7*I9) | M9: =IF(OR(H9="",I9=""),"",H9-7*(I9+J9+K9)) | P9: Not Started | Q9: =IF(OR(M9="",P9="Approved",P9="Approved as Noted"),"",M9-TODAY()) | R9: Added by Claude | S9: Recurring, monthly | T9: Submit draft copy of Application for Payment seven days prior to due date for review by Architect.
A10: 012900.03 | B10: 0 | C10: Applications for Payment (three signed and notarized PDF copies, by email) | D10: 01 29 00 | E10: Payment Procedures | F10: REPORT | G10: 1.4.F p.29 | J10: ='Project Rules'!$B$5 | K10: ='Project Rules'!$B$6 | L10: =IF(OR(H10="",I10=""),"",H10-7*I10) | M10: =IF(OR(H10="",I10=""),"",H10-7*(I10+J10+K10)) | P10: Not Started | Q10: =IF(OR(M10="",P10="Approved",P10="Approved as Noted"),"",M10-TODAY()) | R10: Added by Claude | S10: Recurring, monthly | T10: Submit three signed and notarized PDF copies of each Application for Payment to Architect by email.
A11: 012900.04 | B11: 0 | C11: Waivers of mechanic's lien (partial with each application, conditional final at completion) | D11: 01 29 00 | E11: Payment Procedures | F11: CERT | G11: 1.4.G p.29 | J11: ='Project Rules'!$B$5 | K11: ='Project Rules'!$B$6 | L11: =IF(OR(H11="",I11=""),"",H11-7*I11) | M11: =IF(OR(H11="",I11=""),"",H11-7*(I11+J11+K11)) | P11: Not Started | Q11: =IF(OR(M11="",P11="Approved",P11="Approved as Noted"),"",M11-TODAY()) | R11: Added by Claude | S11: Recurring, with every Application for Payment | T11: With each Application for Payment, submit waivers of mechanic's lien from entities lawfully entitled to file a lien.
A12: 012900.05 | B12: 0 | C12: Initial Application for Payment package: subcontractor list, products list, staff and consultant lists | D12: 01 29 00 | E12: Payment Procedures | F12: REPORT | G12: 1.4.H p.28 | J12: ='Project Rules'!$B$5 | K12: ='Project Rules'!$B$6 | L12: =IF(OR(H12="",I12=""),"",H12-7*I12) | M12: =IF(OR(H12="",I12=""),"",H12-7*(I12+J12+K12)) | P12: Not Started | Q12: =IF(OR(M12="",P12="Approved",P12="Approved as Noted"),"",M12-TODAY()) | R12: Added by Claude | S12: Due with the first Application for Payment | T12: Initial Application for Payment: list of subcontractors, schedule of values, Contractor's construction schedule, products list, submittal schedule, list of staff assignments, list of principal consultants.
A13: 012900.06 | B13: 0 | C13: Building permits, authorizations and licenses from authorities having jurisdiction | D13: 01 29 00 | E13: Payment Procedures | F13: CERT | G13: 1.4.H.8-9 p.29 | J13: ='Project Rules'!$B$5 | K13: ='Project Rules'!$B$6 | L13: =IF(OR(H13="",I13=""),"",H13-7*I13) | M13: =IF(OR(H13="",I13=""),"",H13-7*(I13+J13+K13)) | P13: Not Started | Q13: =IF(OR(M13="",P13="Approved",P13="Approved as Noted"),"",M13-TODAY()) | R13: Added by Claude | S13: Due with the first Application for Payment | T13: Initial Application for Payment: copies of building permits; copies of authorizations and licenses from authorities having jurisdiction.
A14: 013100.01 | B14: 0 | C14: Subcontract List: Prepare a written summary identifying individuals or firms proposed for each portion of the Work, including those who are to furnish products or... | D14: 01 31 00 | E14: Project Management And Coordination | F14: REPORT | G14: 1.3.A p.31 | J14: ='Project Rules'!$B$5 | K14: ='Project Rules'!$B$6 | L14: =IF(OR(H14="",I14=""),"",H14-7*I14) | M14: =IF(OR(H14="",I14=""),"",H14-7*(I14+J14+K14)) | P14: Not Started | Q14: =IF(OR(M14="",P14="Approved",P14="Approved as Noted"),"",M14-TODAY()) | R14: Spec article | T14: Subcontract List: Prepare a written summary identifying individuals or firms proposed for each portion of the Work, including those who are to furnish products or equipment fabricated to a special design. Include the following information in tabular form: 1. Name, address, telephone number, and email address of entity performing subcontract or supplying products. 2. Number and title of related Specification Section(s) covered by subcontract. 3. Drawing number and detail references, as appropriate, covered by subcontract.
A15: 013100.02 | B15: 0 | C15: Key Personnel Names: 15 days prior to starting construction operations, submit a list of key personnel assignments, including superintendent and other personnel in... | D15: 01 31 00 | E15: Project Management And Coordination | F15: REPORT | G15: 1.3.B p.31 | J15: ='Project Rules'!$B$5 | K15: ='Project Rules'!$B$6 | L15: =IF(OR(H15="",I15=""),"",H15-7*I15) | M15: =IF(OR(H15="",I15=""),"",H15-7*(I15+J15+K15)) | P15: Not Started | Q15: =IF(OR(M15="",P15="Approved",P15="Approved as Noted"),"",M15-TODAY()) | R15: Spec article | T15: Key Personnel Names: 15 days prior to starting construction operations, submit a list of key personnel assignments, including superintendent and other personnel in attendance at Project site. Identify individuals and their duties and responsibilities; list addresses, cellular telephone numbers, and e-mail addresses. Provide names, addresses, and telephone numbers of individuals assigned as alternates in the absence of individuals assigned to Project. 1. Post copies of list in Project meeting room, in temporary field office, in web-based Project software directory, and in prominent location in built facility. Keep list current at all times.
A16: 013200.01 | B16: 0 | C16: Construction schedule files: working electronic copy and PDF | D16: 01 32 00 | E16: Construction Progress Documentation | F16: SCHED | G16: 1.3.A.1 p.38 | J16: ='Project Rules'!$B$5 | K16: ='Project Rules'!$B$6 | L16: =IF(OR(H16="",I16=""),"",H16-7*I16) | M16: =IF(OR(H16="",I16=""),"",H16-7*(I16+J16+K16)) | P16: Not Started | Q16: =IF(OR(M16="",P16="Approved",P16="Approved as Noted"),"",M16-TODAY()) | R16: Spec article | T16: Working electronic copy of schedule file.
A17: 013200.02 | B17: 0 | C17: Startup Network Diagram: Of size required to display entire network for entire construction period. | D17: 01 32 00 | E17: Construction Progress Documentation | F17: SCHED | G17: 1.3.B p.38 | J17: ='Project Rules'!$B$5 | K17: ='Project Rules'!$B$6 | L17: =IF(OR(H17="",I17=""),"",H17-7*I17) | M17: =IF(OR(H17="",I17=""),"",H17-7*(I17+J17+K17)) | P17: Not Started | Q17: =IF(OR(M17="",P17="Approved",P17="Approved as Noted"),"",M17-TODAY()) | R17: Spec article | T17: Startup Network Diagram: Of size required to display entire network for entire construction period. Show logic ties for activities.
A18: 013200.03 | B18: 0 | C18: Contractor's Construction Schedule: Initial schedule, of size required to display entire schedule for entire construction period. | D18: 01 32 00 | E18: Construction Progress Documentation | F18: SCHED | G18: 1.3.C p.38 | J18: ='Project Rules'!$B$5 | K18: ='Project Rules'!$B$6 | L18: =IF(OR(H18="",I18=""),"",H18-7*I18) | M18: =IF(OR(H18="",I18=""),"",H18-7*(I18+J18+K18)) | P18: Not Started | Q18: =IF(OR(M18="",P18="Approved",P18="Approved as Noted"),"",M18-TODAY()) | R18: Spec article | T18: Contractor's Construction Schedule: Initial schedule, of size required to display entire schedule for entire construction period.
A19: 013233.01 | B19: 0 | C19: Key Plan: Submit key plan of Project site and building with notation of vantage points marked for location and direction of each photograph and video recording. | D19: 01 32 33 | E19: Photographic Documentation | F19: REPORT | G19: 1.2.A p.45 | J19: ='Project Rules'!$B$5 | K19: ='Project Rules'!$B$6 | L19: =IF(OR(H19="",I19=""),"",H19-7*I19) | M19: =IF(OR(H19="",I19=""),"",H19-7*(I19+J19+K19)) | P19: Not Started | Q19: =IF(OR(M19="",P19="Approved",P19="Approved as Noted"),"",M19-TODAY()) | R19: Spec article | T19: Key Plan: Submit key plan of Project site and building with notation of vantage points marked for location and direction of each photograph and video recording. Indicate elevation or story of construction. Include same information as corresponding photographic documentation.
A20: 013233.02 | B20: 0 | C20: Digital Photographs: Submit image files within three days of taking photographs. | D20: 01 32 33 | E20: Photographic Documentation | F20: REPORT | G20: 1.2.B p.45 | J20: ='Project Rules'!$B$5 | K20: ='Project Rules'!$B$6 | L20: =IF(OR(H20="",I20=""),"",H20-7*I20) | M20: =IF(OR(H20="",I20=""),"",H20-7*(I20+J20+K20)) | P20: Not Started | Q20: =IF(OR(M20="",P20="Approved",P20="Approved as Noted"),"",M20-TODAY()) | R20: Spec article | T20: Digital Photographs: Submit image files within three days of taking photographs. 1. Submit photos by uploading to web-based Project management software site. Include copy of key plan indicating each photograph's location and direction. 2. Identification: Provide the following information with each image description in file metadata tag: a. Name of Project. b. Name and contact information for photographer. c. Name of Architect. d. Name of Contractor. e. Date photograph was taken. f. Description of location, vantage point, and direction. g. Unique sequential identifier keyed to accompanying key plan.
A21: 013233.03 | B21: 0 | C21: Submit video recordings by uploading to web-based Project management software site. | D21: 01 32 33 | E21: Photographic Documentation | F21: REPORT | G21: 1.2.C.1 p.45 | J21: ='Project Rules'!$B$5 | K21: ='Project Rules'!$B$6 | L21: =IF(OR(H21="",I21=""),"",H21-7*I21) | M21: =IF(OR(H21="",I21=""),"",H21-7*(I21+J21+K21)) | P21: Not Started | Q21: =IF(OR(M21="",P21="Approved",P21="Approved as Noted"),"",M21-TODAY()) | R21: Spec article | T21: Submit video recordings by uploading to web-based Project management software site. Include copy of key plan indicating each video's location and direction.
A22: 013233.04 | B22: 0 | C22: Photographer Qualifications: An individual who has been regularly engaged as a professional photographer of construction projects for not less than three years. | D22: 01 32 33 | E22: Photographic Documentation | F22: REPORT+CERT | G22: 1.2.D p.45 | J22: ='Project Rules'!$B$5 | K22: ='Project Rules'!$B$6 | L22: =IF(OR(H22="",I22=""),"",H22-7*I22) | M22: =IF(OR(H22="",I22=""),"",H22-7*(I22+J22+K22)) | P22: Not Started | Q22: =IF(OR(M22="",P22="Approved",P22="Approved as Noted"),"",M22-TODAY()) | R22: Spec article | T22: Photographer Qualifications: An individual who has been regularly engaged as a professional photographer of construction projects for not less than three years.
A23: 013300.01 | B23: 0 | C23: Submittal schedule: initial (first 60 days, long-lead items) and final | D23: 01 33 00 | E23: Submittal Procedures | F23: SCHED | G23: 1.3.A p.48 | J23: ='Project Rules'!$B$5 | K23: ='Project Rules'!$B$6 | L23: =IF(OR(H23="",I23=""),"",H23-7*I23) | M23: =IF(OR(H23="",I23=""),"",H23-7*(I23+J23+K23)) | P23: Not Started | Q23: =IF(OR(M23="",P23="Approved",P23="Approved as Noted"),"",M23-TODAY()) | R23: Added by Claude | S23: Initial with startup schedule; final with first complete construction schedule | T23: Submit, as an action submittal, a list of submittals in chronological order. Initial schedule with the startup construction schedule; final schedule with the first complete construction schedule.
A24: 013300.02 | B24: 0 | C24: Delegated-design services certification, signed and sealed by the design professional | D24: 01 33 00 | E24: Submittal Procedures | F24: CERT | G24: 1.7.B p.52 | J24: ='Project Rules'!$B$5 | K24: ='Project Rules'!$B$6 | L24: =IF(OR(H24="",I24=""),"",H24-7*I24) | M24: =IF(OR(H24="",I24=""),"",H24-7*(I24+J24+K24)) | P24: Not Started | Q24: =IF(OR(M24="",P24="Approved",P24="Approved as Noted"),"",M24-TODAY()) | R24: Added by Claude | S24: Only for products assigned as delegated design | T24: Submit digitally signed PDF certificate, signed and sealed by the responsible design professional, for each product and system assigned to the Contractor to design or certify.
A25: 013513.01 | B25: 0 | C25: Noise schedule: demolition and noisy operations with dates, times and duration | D25: 01 35 13 | E25: Hospital Project Procedures | F25: SCHED | G25: 1.4.A.3 p.54 | J25: ='Project Rules'!$B$5 | K25: ='Project Rules'!$B$6 | L25: =IF(OR(H25="",I25=""),"",H25-7*I25) | M25: =IF(OR(H25="",I25=""),"",H25-7*(I25+J25+K25)) | P25: Not Started | Q25: =IF(OR(M25="",P25="Approved",P25="Approved as Noted"),"",M25-TODAY()) | R25: Added by Claude | S25: As soon as practicable | T25: Submit "Noise Schedule" as soon as practicable indicating type of demolition and other noise inducing construction operations showing dates, times, and duration of such work.
A26: 013516.01 | B26: 0 | C26: Submit alteration work subschedule within seven days of date established for commencement of alteration work. | D26: 01 35 16 | E26: Alteration Project Procedures | F26: SCHED | G26: 1.5.A.1 p.59 | J26: ='Project Rules'!$B$5 | K26: ='Project Rules'!$B$6 | L26: =IF(OR(H26="",I26=""),"",H26-7*I26) | M26: =IF(OR(H26="",I26=""),"",H26-7*(I26+J26+K26)) | P26: Not Started | Q26: =IF(OR(M26="",P26="Approved",P26="Approved as Noted"),"",M26-TODAY()) | R26: Spec article | T26: Submit alteration work subschedule within seven days of date established for commencement of alteration work.
A27: 013516.02 | B27: 0 | C27: Preconstruction Documentation: Show preexisting conditions of adjoining construction and site improvements that are to remain, including finish surfaces, that might be... | D27: 01 35 16 | E27: Alteration Project Procedures | F27: REPORT | G27: 1.5.B p.59 | J27: ='Project Rules'!$B$5 | K27: ='Project Rules'!$B$6 | L27: =IF(OR(H27="",I27=""),"",H27-7*I27) | M27: =IF(OR(H27="",I27=""),"",H27-7*(I27+J27+K27)) | P27: Not Started | Q27: =IF(OR(M27="",P27="Approved",P27="Approved as Noted"),"",M27-TODAY()) | R27: Spec article | T27: Preconstruction Documentation: Show preexisting conditions of adjoining construction and site improvements that are to remain, including finish surfaces, that might be misconstrued as damage caused by Contractor's alteration work operations.
A28: 013516.03 | B28: 0 | C28: Alteration Work Program: Submit 30 days before work begins. | D28: 01 35 16 | E28: Alteration Project Procedures | F28: REPORT | G28: 1.5.C p.59 | J28: ='Project Rules'!$B$5 | K28: ='Project Rules'!$B$6 | L28: =IF(OR(H28="",I28=""),"",H28-7*I28) | M28: =IF(OR(H28="",I28=""),"",H28-7*(I28+J28+K28)) | P28: Not Started | Q28: =IF(OR(M28="",P28="Approved",P28="Approved as Noted"),"",M28-TODAY()) | R28: Spec article | T28: Alteration Work Program: Submit 30 days before work begins.
A29: 013516.04 | B29: 0 | C29: Fire-Prevention Plan: Submit 30 days before work begins. | D29: 01 35 16 | E29: Alteration Project Procedures | F29: REPORT | G29: 1.5.D p.59 | J29: ='Project Rules'!$B$5 | K29: ='Project Rules'!$B$6 | L29: =IF(OR(H29="",I29=""),"",H29-7*I29) | M29: =IF(OR(H29="",I29=""),"",H29-7*(I29+J29+K29)) | P29: Not Started | Q29: =IF(OR(M29="",P29="Approved",P29="Approved as Noted"),"",M29-TODAY()) | R29: Spec article | T29: Fire-Prevention Plan: Submit 30 days before work begins.
A30: 014000.01 | B30: 0 | C30: Mockup shop drawings: plans, sections, elevations, details, components and axonometrics | D30: 01 40 00 | E30: Quality Requirements | F30: SD | G30: 1.5.A p.64 | J30: ='Project Rules'!$B$5 | K30: ='Project Rules'!$B$6 | L30: =IF(OR(H30="",I30=""),"",H30-7*I30) | M30: =IF(OR(H30="",I30=""),"",H30-7*(I30+J30+K30)) | P30: Not Started | Q30: =IF(OR(M30="",P30="Approved",P30="Approved as Noted"),"",M30-TODAY()) | R30: Spec article (merged) | S30: Only for mockups the sections require | T30: Include plans, sections, elevations, and details, indicating materials and size of mockup construction. Indicate manufacturer and model number of individual components. Provide axonometric drawings for conditions difficult to illustrate in two dimensions.
A31: 014000.02 | B31: 0 | C31: Contractor's Quality-Control Plan: For quality-assurance and quality-control activities and responsibilities. | D31: 01 40 00 | E31: Quality Requirements | F31: REPORT | G31: 1.6.A p.64 | J31: ='Project Rules'!$B$5 | K31: ='Project Rules'!$B$6 | L31: =IF(OR(H31="",I31=""),"",H31-7*I31) | M31: =IF(OR(H31="",I31=""),"",H31-7*(I31+J31+K31)) | P31: Not Started | Q31: =IF(OR(M31="",P31="Approved",P31="Approved as Noted"),"",M31-TODAY()) | R31: Spec article | T31: Contractor's Quality-Control Plan: For quality-assurance and quality-control activities and responsibilities.
A32: 014000.03 | B32: 0 | C32: Qualification Data: For Contractor's quality-control personnel. | D32: 01 40 00 | E32: Quality Requirements | F32: CERT | G32: 1.6.B p.64 | J32: ='Project Rules'!$B$5 | K32: ='Project Rules'!$B$6 | L32: =IF(OR(H32="",I32=""),"",H32-7*I32) | M32: =IF(OR(H32="",I32=""),"",H32-7*(I32+J32+K32)) | P32: Not Started | Q32: =IF(OR(M32="",P32="Approved",P32="Approved as Noted"),"",M32-TODAY()) | R32: Spec article | T32: Qualification Data: For Contractor's quality-control personnel.
A33: 014000.04 | B33: 0 | C33: Contractor's Statement of Responsibility: When required by authorities having jurisdiction, submit copy of written statement of responsibility submitted to authorities... | D33: 01 40 00 | E33: Quality Requirements | F33: REPORT | G33: 1.6.C p.64 | J33: ='Project Rules'!$B$5 | K33: ='Project Rules'!$B$6 | L33: =IF(OR(H33="",I33=""),"",H33-7*I33) | M33: =IF(OR(H33="",I33=""),"",H33-7*(I33+J33+K33)) | P33: Not Started | Q33: =IF(OR(M33="",P33="Approved",P33="Approved as Noted"),"",M33-TODAY()) | R33: Spec article | T33: Contractor's Statement of Responsibility: When required by authorities having jurisdiction, submit copy of written statement of responsibility submitted to authorities having jurisdiction before starting work on the following systems: 1. Primary wind-force-resisting system or a wind-resisting component listed in the Statement of Special Inspections.
A34: 014000.05 | B34: 0 | C34: Testing Agency Qualifications: For testing agencies specified in "Quality Assurance" Article to demonstrate their capabilities and experience. | D34: 01 40 00 | E34: Quality Requirements | F34: CERT | G34: 1.6.D p.64 | J34: ='Project Rules'!$B$5 | K34: ='Project Rules'!$B$6 | L34: =IF(OR(H34="",I34=""),"",H34-7*I34) | M34: =IF(OR(H34="",I34=""),"",H34-7*(I34+J34+K34)) | P34: Not Started | Q34: =IF(OR(M34="",P34="Approved",P34="Approved as Noted"),"",M34-TODAY()) | R34: Spec article | T34: Testing Agency Qualifications: For testing agencies specified in "Quality Assurance" Article to demonstrate their capabilities and experience. Include proof of qualifications in the form of a recent report on the inspection of the testing agency by a recognized authority.
A35: 014000.06 | B35: 0 | C35: Schedule of Tests and Inspections: Prepare in tabular form and include the following: 1. | D35: 01 40 00 | E35: Quality Requirements | F35: SCHED | G35: 1.6.E p.64 | J35: ='Project Rules'!$B$5 | K35: ='Project Rules'!$B$6 | L35: =IF(OR(H35="",I35=""),"",H35-7*I35) | M35: =IF(OR(H35="",I35=""),"",H35-7*(I35+J35+K35)) | P35: Not Started | Q35: =IF(OR(M35="",P35="Approved",P35="Approved as Noted"),"",M35-TODAY()) | R35: Spec article | T35: Schedule of Tests and Inspections: Prepare in tabular form and include the following: 1. Specification Section number and title. 2. Entity responsible for performing tests and inspections. 3. Description of test and inspection.
A36: 015000.01 | B36: 0 | C36: Site Utilization Plan: Show temporary facilities, temporary utility lines and connections, staging areas, construction site entrances, vehicle circulation, and parking... | D36: 01 50 00 | E36: Temporary Facilities And Controls | F36: REPORT | G36: 1.3.A p.71 | J36: ='Project Rules'!$B$5 | K36: ='Project Rules'!$B$6 | L36: =IF(OR(H36="",I36=""),"",H36-7*I36) | M36: =IF(OR(H36="",I36=""),"",H36-7*(I36+J36+K36)) | P36: Not Started | Q36: =IF(OR(M36="",P36="Approved",P36="Approved as Noted"),"",M36-TODAY()) | R36: Spec article | T36: Site Utilization Plan: Show temporary facilities, temporary utility lines and connections, staging areas, construction site entrances, vehicle circulation, and parking areas for construction personnel.
A37: 015000.02 | B37: 0 | C37: Implementation and Termination Schedule: Within 15 days of date established for commencement of the Work, submit schedule indicating implementation and termination dates... | D37: 01 50 00 | E37: Temporary Facilities And Controls | F37: SCHED | G37: 1.3.B p.71 | J37: ='Project Rules'!$B$5 | K37: ='Project Rules'!$B$6 | L37: =IF(OR(H37="",I37=""),"",H37-7*I37) | M37: =IF(OR(H37="",I37=""),"",H37-7*(I37+J37+K37)) | P37: Not Started | Q37: =IF(OR(M37="",P37="Approved",P37="Approved as Noted"),"",M37-TODAY()) | R37: Spec article | T37: Implementation and Termination Schedule: Within 15 days of date established for commencement of the Work, submit schedule indicating implementation and termination dates of each temporary utility.
A38: 015000.03 | B38: 0 | C38: Project Identification and Temporary Signs: Show fabrication and installation details, including plans, elevations, details, layouts, typestyles, graphic elements, and... | D38: 01 50 00 | E38: Temporary Facilities And Controls | F38: REPORT | G38: 1.3.C p.71 | J38: ='Project Rules'!$B$5 | K38: ='Project Rules'!$B$6 | L38: =IF(OR(H38="",I38=""),"",H38-7*I38) | M38: =IF(OR(H38="",I38=""),"",H38-7*(I38+J38+K38)) | P38: Not Started | Q38: =IF(OR(M38="",P38="Approved",P38="Approved as Noted"),"",M38-TODAY()) | R38: Spec article | T38: Project Identification and Temporary Signs: Show fabrication and installation details, including plans, elevations, details, layouts, typestyles, graphic elements, and message content.
A39: 015000.04 | B39: 0 | C39: Fire-Safety Program: Show compliance with requirements of NFPA 241 and authorities having jurisdiction. | D39: 01 50 00 | E39: Temporary Facilities And Controls | F39: REPORT | G39: 1.3.D p.71 | J39: ='Project Rules'!$B$5 | K39: ='Project Rules'!$B$6 | L39: =IF(OR(H39="",I39=""),"",H39-7*I39) | M39: =IF(OR(H39="",I39=""),"",H39-7*(I39+J39+K39)) | P39: Not Started | Q39: =IF(OR(M39="",P39="Approved",P39="Approved as Noted"),"",M39-TODAY()) | R39: Spec article | T39: Fire-Safety Program: Show compliance with requirements of NFPA 241 and authorities having jurisdiction. Indicate Contractor personnel responsible for management of fire-prevention program.
A40: 015000.05 | B40: 0 | C40: Moisture- and Mold-Protection Plan: Describe procedures and controls for protecting materials and construction from water absorption and damage and mold. | D40: 01 50 00 | E40: Temporary Facilities And Controls | F40: REPORT | G40: 1.3.E p.71 | J40: ='Project Rules'!$B$5 | K40: ='Project Rules'!$B$6 | L40: =IF(OR(H40="",I40=""),"",H40-7*I40) | M40: =IF(OR(H40="",I40=""),"",H40-7*(I40+J40+K40)) | P40: Not Started | Q40: =IF(OR(M40="",P40="Approved",P40="Approved as Noted"),"",M40-TODAY()) | R40: Spec article | T40: Moisture- and Mold-Protection Plan: Describe procedures and controls for protecting materials and construction from water absorption and damage and mold. Describe delivery, handling, storage, installation, and protection provisions for materials subject to water absorption or water damage. 1. Indicate procedures for discarding water-damaged materials, protocols for mitigating water intrusion into completed Work, and requirements for replacing water-damaged Work. 2. Indicate sequencing of work that requires water, such as sprayed fire-resistive materials, plastering, and terrazzo grinding, and describe plans for dealing with water from these operations. Show procedures for verifying that wet construction has dried sufficiently to permit installation of finish materials. 3. Indicate methods to be used to avoid trapping water in finished work.
A41: 015000.06 | B41: 0 | C41: Dust- and HVAC-Control Plan: Submit coordination drawing and narrative that indicates the dust- and HVAC-control measures proposed for use, proposed locations, and... | D41: 01 50 00 | E41: Temporary Facilities And Controls | F41: REPORT+SD | G41: 1.3.F p.71 | J41: ='Project Rules'!$B$5 | K41: ='Project Rules'!$B$6 | L41: =IF(OR(H41="",I41=""),"",H41-7*I41) | M41: =IF(OR(H41="",I41=""),"",H41-7*(I41+J41+K41)) | P41: Not Started | Q41: =IF(OR(M41="",P41="Approved",P41="Approved as Noted"),"",M41-TODAY()) | R41: Spec article | T41: Dust- and HVAC-Control Plan: Submit coordination drawing and narrative that indicates the dust- and HVAC-control measures proposed for use, proposed locations, and proposed time frame for their operation. Include the following: 1. Locations of dust-control partitions at each phase of work. 2. HVAC system isolation schematic drawing. 3. Location of proposed air-filtration system discharge. 4. Waste-handling procedures. 5. Other dust-control measures.
...

Sheet Project Rules
A1: Project Rules
A2: Yellow cells are inputs. The Register sheet reads the review and prep weeks from here.
A4: Project | B4: Radiology Room E.D. Vol B
A5: Default review time (weeks) | B5: 2.14
A6: Default prep time (weeks) | B6: 1
A7: Numbering format | B7: Specification Section number, a sequential alphanumeric identifier, and an alphanumeric suffix for each resubmittal (for example 092913.01, then 092913.01.A).
A8: Copies and format | B8: Submit as PDF uploaded to the web-based project management software, with a paper transmittal when required. Samples for verification: three sets (Architect keeps two). Shop drawings and design data: six copies plus one electronic copy where a section states a count. Action and informational submittals from the same section go in separate packages.
A9: Source of rules | B9: Section 01 33 00 Submittal Procedures (pages 48 to 53), Section 01 77 00 Closeout Procedures, Section 01 29 00 Payment Procedures
A11: Project-wide submittal requirements
A12: 1. | B12: Initial review is 15 days (about 2.1 weeks) from the Architect's receipt. Each resubmittal review is another 15 days. Where sequential review by consultants or the Owner is indicated, allow 21 days for the initial review.
A13: 2. | B13: No extension of Contract Time is allowed for submittals sent too late to be processed, including resubmittals.
A14: 3. | B14: Initial submittal schedule must cover the first 60 days of construction and any long-lead items, and goes in with the startup construction schedule. The final schedule goes in with the first complete construction schedule.
A15: 4. | B15: Submit all items for a section together unless the approved submittal schedule allows partial submittals. Submit product data before shop drawings, and before or with samples.
A16: 5. | B16: Indicate deviations from the Contract Documents on each submittal, and identify options that need the Architect's selection.
A17: 6. | B17: The Architect returns without review any submittal that is incomplete, not reviewed and approved by the Contractor, received from anyone but the Contractor, or not required by the Contract Documents.
A18: 7. | B18: Use only final action submittals marked with the Architect's approval notation for construction.
A19: 8. | B19: Closeout items are due at least 10 days before the Substantial Completion inspection request.
A20: 9. | B20: Substitution requests (Section 01 25 00) are contractor-initiated and are not in this register.
A21: 10. | B21: Fire protection piping and sprinkler shop drawings go to the local Fire Marshal and the Owner's insurance underwriter before the Architect.
A22: 11. | B22: Prep time of 1 week is an assumption, not a spec requirement.

Sheet Review Queue
A1: Review Queue
A2: Items the extraction could not place with confidence. Confirm each, then edit or delete its row on the Register sheet.
A4: Sub # | B4: Spec Section | C4: Section Title | D4: Spec Ref | E4: Type | F4: Why it needs review | G4: Spec text | H4: Decision
A5: 013300.02 | B5: 01 33 00 | C5: Submittal Procedures | D5: 1.7.B p.52 | E5: CERT | F5: Applies only where a section assigns design to the Contractor. Radiology Vol B has 05 45 23 (metal supports) and 09 22 16 (metal framing). Confirm others. | G5: Submit digitally signed PDF certificate, signed and sealed by the responsible design professional, for each product and system assigned to the Contractor to design or certify.
A6: 134900.04 | B6: 13 49 00 | C6: Radiation Protection | D6: 1.5.A p.198 | E6: CERT | F6: Text says flush wood door manufacturer under a radiation protection section. Probably a carry-over. Confirm. | G6: Qualification Data: For flush wood door manufacturer.
A7: 211100.01 | B7: 21 11 00 | C7: Fire Protection Piping | D7: 1.05.A-D p.222 | E7: SD+PD+CALC | F7: Review time for the Fire Marshal and insurance underwriter is not stated. Confirm lead time with the sprinkler contractor. | G7: Prior to submittal to Architect, submit shop drawings, product data, and hydraulic calculations to local Fire Marshal and Owner's Insurance. After approval from local Fire Marshal and Owner's Insurance Underwriter, submit shop drawings, product data, and hydraulic calculations to Architect (with Certificate of Approval from local Fire Marshal and Owner's Insurance Underwriter for approval in accordance with Division 01 and Section 21 0010. Indicate pipe materials used, jointing methods, supports, floor and wall penetration seals. Indicate valve data and ratings.
A8: 211300.01 | B8: 21 13 00 | C8: Automatic Sprinkler Systems | D8: 1.06.A-C p.224 | E8: SD+PD+CALC | F8: Review time for the Fire Marshal and insurance underwriter is not stated. Confirm lead time with the sprinkler contractor. | G8: Prior to submittal to Architect submit shop drawings, product data, and hydraulic calculations to local Fire Marshal and Owner's Insurance Underwriter. After approval from local Fire Marshal and Owner's Insurance Underwriter submit shop drawings, product data and hydraulic calculations to Architect (with Certificate of Approval from local Fire Marshal and Owner's Insurance Underwriter) for approval in accordance with Division 01 and Section 21 0010. Indicate hydraulic calculations, detailed pipe layout, hangers and supports, components and accessories.
A9: 220529.01 | B9: 22 05 29 | C9: Plumbing Supports And Anchors | D9: 1.03.A p.240 | E9: PD | F9: Reads as a cross-reference to Division 01. Likely a duplicate of 1.03.B. | G9: Submit product data as required under provisions of Division 01 and Section 22 0010.
A10: 260527.01 | B10: 26 05 27 | C10: Sealing Of Penetrations | D10: 1.02.A p.333 | E10: SAM | F10: Request-only item. Confirm whether to track it. | G10: Samples: Provide samples upon written request.
A11: 265113.03 | B11: 26 51 13 | C11: Lighting | D11: 1.02.C p.353 | E11: SAM | F11: Request-only item. Confirm whether to track it. | G11: If required by Architect, submit samples of lighting fixtures for approval.

Sheet By Section
A1: Submittals by Spec Section
A3: Spec Section | B3: Section Title | C3: Submittals | D3: Approved | E3: Open
A4: 01 21 00 | B4: Allowances | C4: =COUNTIF(Register!$D$5:$D$247,A4) | D4: =COUNTIFS(Register!$D$5:$D$247,A4,Register!$P$5:$P$247,"Approved")+COUNTIFS(Register!$D$5:$D$247,A4,Register!$P$5:$P$247,"Approved as Noted") | E4: =C4-D4
A5: 01 29 00 | B5: Payment Procedures | C5: =COUNTIF(Register!$D$5:$D$247,A5) | D5: =COUNTIFS(Register!$D$5:$D$247,A5,Register!$P$5:$P$247,"Approved")+COUNTIFS(Register!$D$5:$D$247,A5,Register!$P$5:$P$247,"Approved as Noted") | E5: =C5-D5
A6: 01 31 00 | B6: Project Management And Coordination | C6: =COUNTIF(Register!$D$5:$D$247,A6) | D6: =COUNTIFS(Register!$D$5:$D$247,A6,Register!$P$5:$P$247,"Approved")+COUNTIFS(Register!$D$5:$D$247,A6,Register!$P$5:$P$247,"Approved as Noted") | E6: =C6-D6
A7: 01 32 00 | B7: Construction Progress Documentation | C7: =COUNTIF(Register!$D$5:$D$247,A7) | D7: =COUNTIFS(Register!$D$5:$D$247,A7,Register!$P$5:$P$247,"Approved")+COUNTIFS(Register!$D$5:$D$247,A7,Register!$P$5:$P$247,"Approved as Noted") | E7: =C7-D7
A8: 01 32 33 | B8: Photographic Documentation | C8: =COUNTIF(Register!$D$5:$D$247,A8) | D8: =COUNTIFS(Register!$D$5:$D$247,A8,Register!$P$5:$P$247,"Approved")+COUNTIFS(Register!$D$5:$D$247,A8,Register!$P$5:$P$247,"Approved as Noted") | E8: =C8-D8
A9: 01 33 00 | B9: Submittal Procedures | C9: =COUNTIF(Register!$D$5:$D$247,A9) | D9: =COUNTIFS(Register!$D$5:$D$247,A9,Register!$P$5:$P$247,"Approved")+COUNTIFS(Register!$D$5:$D$247,A9,Register!$P$5:$P$247,"Approved as Noted") | E9: =C9-D9
A10: 01 35 13 | B10: Hospital Project Procedures | C10: =COUNTIF(Register!$D$5:$D$247,A10) | D10: =COUNTIFS(Register!$D$5:$D$247,A10,Register!$P$5:$P$247,"Approved")+COUNTIFS(Register!$D$5:$D$247,A10,Register!$P$5:$P$247,"Approved as Noted") | E10: =C10-D10
A11: 01 35 16 | B11: Alteration Project Procedures | C11: =COUNTIF(Register!$D$5:$D$247,A11) | D11: =COUNTIFS(Register!$D$5:$D$247,A11,Register!$P$5:$P$247,"Approved")+COUNTIFS(Register!$D$5:$D$247,A11,Register!$P$5:$P$247,"Approved as Noted") | E11: =C11-D11
A12: 01 40 00 | B12: Quality Requirements | C12: =COUNTIF(Register!$D$5:$D$247,A12) | D12: =COUNTIFS(Register!$D$5:$D$247,A12,Register!$P$5:$P$247,"Approved")+COUNTIFS(Register!$D$5:$D$247,A12,Register!$P$5:$P$247,"Approved as Noted") | E12: =C12-D12
A13: 01 50 00 | B13: Temporary Facilities And Controls | C13: =COUNTIF(Register!$D$5:$D$247,A13) | D13: =COUNTIFS(Register!$D$5:$D$247,A13,Register!$P$5:$P$247,"Approved")+COUNTIFS(Register!$D$5:$D$247,A13,Register!$P$5:$P$247,"Approved as Noted") | E13: =C13-D13
A14: 01 57 19 | B14: Temporary Environmental Controls | C14: =COUNTIF(Register!$D$5:$D$247,A14) | D14: =COUNTIFS(Register!$D$5:$D$247,A14,Register!$P$5:$P$247,"Approved")+COUNTIFS(Register!$D$5:$D$247,A14,Register!$P$5:$P$247,"Approved as Noted") | E14: =C14-D14
A15: 01 73 00 | B15: Execution | C15: =COUNTIF(Register!$D$5:$D$247,A15) | D15: =COUNTIFS(Register!$D$5:$D$247,A15,Register!$P$5:$P$247,"Approved")+COUNTIFS(Register!$D$5:$D$247,A15,Register!$P$5:$P$247,"Approved as Noted") | E15: =C15-D15
... A76: 27 05 28 | B76: Empty Conduit Systems | C76: =COUNTIF(Register!$D$5:$D$247,A76) | D76: =COUNTIFS(Register!$D$5:$D$247,A76,Register!$P$5:$P$247,"Approved")+COUNTIFS(Register!$D$5:$D$247,A76,Register!$P$5:$P$247,"Approved as Noted") | E76: =C76-D76
A77: Total | C77: =SUM(C4:C76) | D77: =SUM(D4:D76) | E77: =SUM(E4:E76)

Sheet Legend
A1: Legend
A3: Type code | B3: Meaning
A4: PD | B4: Product data
A5: SD | B5: Shop drawings
A6: WD | B6: Wiring diagrams
A7: SAM | B7: Samples
A8: CALC | B8: Calculations
A9: CERT | B9: Certificates, qualifications
A10: TEST | B10: Test and inspection reports
A11: WARR | B11: Warranties
A12: OM | B12: Operation and maintenance data
A13: MOCKUP | B13: Mock-ups
A14: RECORD | B14: Record drawings and as-builts
... A18: OTHER | B18: Not classified
A20: Cell colors
B21: Input: edit these
B22: Needs a human decision
B23: Blue text: typed number. Green text: value linked from Project Rules. Black: formula or text.
